Workbook

Sheet README
A2: The present Excel file implements simulations of the effect of a minimum wealth tax on the progressivity of the tax system and on fiscal revenues, for different countries.
A4: DATA SOURCES
A6: The file contains one sheet per data sources, containing the data which is used as input to the simulations. Specifically, we use the following studies on income distribution and tax prgressivity in different countries:
A8: Laurent Bach, Antoine Bozio, Arthur Guillouzouic, Clément Malgouyres (2025). Do Billionaires Pay Taxes?
A9: Insee (2026). Comptes nationaux distribués 2023, base 2020. CND.101 - Comptes nationaux distribués selon les vingtièmes de niveau de vie usuel
A10: Thomas Piketty, Emmanuel Saez, Gabriel Zucman (2018). Distributional National Accounts: Methods and Estimates for the United States.
A11: Akcan S. Balkir, Emmanuel Saez, Danny Yagan, Gabriel Zucman (2025). How Much Tax Do US Billionaires Pay? Evidence From Administrative Data.
A12: Theo Palomo, Davi Bhering, Thiago Scot, Pierre Bachas, Luciana Barcarolo, Celso Campos, Javier Feinmann, Leonardo Moreira, Gabriel Zucman (2025). Tax Progressivity and Inequality in Brazil: Evidence from Integrated Administrative Data.
A13: Arjan Bruil, Céline van Essen, Wouter Leenders, Arjan Lejour, Jan Möhlmann, Simon Rabaté (2025). Inequality and Redistribution in the Netherlands
A14: Demetrio Guzzardi, Elisa Palagi, Andrea Roventini, Alessandro Santoro (2024). Reconstructing Income Inequality in Italy: New Evidence and Tax System Implications from Distributional National Accounts.
A16: METHOD AND ASSUMPTIONS
A18: The simulations of tax rates and tax revenues rely on:
B20: (i) Some data tabulations describing the distribution of pre-tax income and tax rate by pre-tax income group.
B21: See Data sources. All the articles follow the same methodology and provide country-specific results in a standardized way.
B23: (ii) Some assumptions regarding the link between wealth distribution and income distribution. Specifically, we make assumptions about:
C25: (a) The income to wealth ratio within each group.
C26: Income to wealth ratio is assumed uniform over each income group.
C27: In all countries, it is taken equal to 13.0% for P99-P99.9, 10.8% for for P99.9-P99.99, 8.3% for for P99.99-P99.999, and 7.4% for P99.999-Billionaires.
C28: For billionaires, we use country specific assumptions based on the US benchmark (4,9%), that we adjust according to average wealth reported in Bilionnaires lists.
C30: See 'Income to wealth ratios' sheet.
C31: This assumption is necessary for computing the wealth tax liabilities from the income data.
C32: The only country for which there exist reliable estimates of income to wealth ratios at the very top of the income distribution is the US.
C33: US DINA files (PSZ 2018) for year 2024 show a ratio of 13,0% for P99-P99.9, 10,8% for for P99.9-P99.99, 8,3% for for P99.99-P99.999, and 7,4% for P99.999-P99.9998. See 'Income to wealth ratios' sheet.
C34: For the purpose of the simulations, we extrapolate these ratios to the other countries.
C35: Balkir et al (2025) find an income to wealth ratio of 4.9% for the top 400 billionnaires (after excluding pure realized capital gains) for years 2018-2020.
C36: For other countries, we adjust this benchmark based on some calibrations made from the average wealth per billionaire recorded in the Forbes list.
C38: (b) The distribution of wealth/income within each income group.
... C40: This assumption allows a flexible choice of wealth threshold for the simulated wealth tax.
B42: (iii) Some assumptions on the nominal income growth rate by income group.
B43: We use nominal income growth rates by income group and by country from the World Inequality Database.
B45: See 'WID' sheet and wid.world.
B46: This assumption is necessary for ageing the values of income by group from the year they are based on to 2025, in order to compute fiscal revenues for year 2025.
B47: We choose not to directly use the income distribution from the WID because the income distribution provided in each country-specific study is more granular (up to the top 0,0001% income group)
B48: than the WID data (which only goes up to the top 0,001% income group). We however apply distinct growth rates to the average income and to the income threshold of each group, based on the observed
B49: growth rates of these two variables in WID data, for each group and each country. This allows to account for changes in the income distribution that are captured by WID data.
A51: See the country-specific sheets for details of the simulation method applied from these data and assumptions. The method is the same for all the countries.
A53: ONLINE SIMULATIONS
A55: The online simulator exactly replicates the simulation method implemented in this Excel file.
A56: For each country and each income group, the 'Data' and 'Assumptions' values are provided as input to the simulations.
A57: The website then replicates the calculations implemented in the 'Simulations' columns, depending on the reform parameters chosen by the user.
...

Sheet FRA
B2: Data (2016) | H2: Assumptions | L2: Simulations (2025)
A3: Group | B3: Number of units | C3: Income share | D3: Average income | E3: Income threshold | F3: Total tax rate | G3: Individual tax rate | H3: Income / Wealth Ratio | I3: Nominal growth rate (average) | J3: Nominal growth rate (threshold) | K3: Population growth | L3: Current wealth tax rate | M3: Average income | N3: Income threshold | O3: Wealth threshold | P3: Patero coefficient alpha | Q3: Corrected alpha | R3: Share of wealth exposed | S3: Number of units exposed | T3: Current tax rate | U3: Tax rate under reform | V3: Extra fiscal revenues
A4: P0-P10 | B4: ='Bach et al. (2025)'!C4-'Bach et al. (2025)'!C5 -> 3783411 | C4: =('Bach et al. (2025)'!F4-'Bach et al. (2025)'!F5)/100 -> 0.0015 | F4: ='Insee (2026)'!C91 -> 0.58519002
A5: P10-P20 | B5: ='Bach et al. (2025)'!C5-'Bach et al. (2025)'!C6 -> 3783612 | C5: =('Bach et al. (2025)'!F5-'Bach et al. (2025)'!F6)/100 -> 0.021 | F5: ='Insee (2026)'!E91 -> 0.44220761 | T5: =F5 -> 0.44220761 | U5: =T5 -> 0.44220761
A6: P20-P30 | B6: ='Bach et al. (2025)'!C6-'Bach et al. (2025)'!C7 -> 3783029 | C6: =('Bach et al. (2025)'!F6-'Bach et al. (2025)'!F7)/100 -> 0.0371 | F6: ='Insee (2026)'!G91 -> 0.44212399 | T6: =F6 -> 0.44212399 | U6: =T6 -> 0.44212399
A7: P30-P40 | B7: ='Bach et al. (2025)'!C7-'Bach et al. (2025)'!C8 -> 3783555 | C7: =('Bach et al. (2025)'!F7-'Bach et al. (2025)'!F8)/100 -> 0.0486 | F7: ='Insee (2026)'!I91 -> 0.46266399 | T7: =F7 -> 0.46266399 | U7: =T7 -> 0.46266399
A8: P40-P50 | B8: ='Bach et al. (2025)'!C8-'Bach et al. (2025)'!C9 -> 3783954 | C8: =('Bach et al. (2025)'!F8-'Bach et al. (2025)'!F9)/100 -> 0.062 | F8: ='Insee (2026)'!K91 -> 0.48163197 | T8: =F8 -> 0.48163197 | U8: =T8 -> 0.48163197
A9: P50-P60 | B9: ='Bach et al. (2025)'!C9-'Bach et al. (2025)'!C10 -> 3782935 | C9: =('Bach et al. (2025)'!F9-'Bach et al. (2025)'!F10)/100 -> 0.0736 | F9: ='Insee (2026)'!M91 -> 0.49227262 | T9: =F9 -> 0.49227262 | U9: =T9 -> 0.49227262
A10: P60-P70 | B10: ='Bach et al. (2025)'!C10-'Bach et al. (2025)'!C11 -> 3783286 | C10: =('Bach et al. (2025)'!F10-'Bach et al. (2025)'!F11)/100 -> 0.0915 | F10: ='Insee (2026)'!O91 -> 0.51497106 | T10: =F10 -> 0.51497106 | U10: =T10 -> 0.51497106
A11: P70-P80 | B11: ='Bach et al. (2025)'!C11-'Bach et al. (2025)'!C12 -> 3783032 | C11: =('Bach et al. (2025)'!F11-'Bach et al. (2025)'!F12)/100 -> 0.117 | F11: ='Insee (2026)'!Q91 -> 0.53154438 | T11: =F11 -> 0.53154438 | U11: =T11 -> 0.53154438
A12: P80-P90 | B12: ='Bach et al. (2025)'!C12-'Bach et al. (2025)'!C13 -> 3783370 | C12: =('Bach et al. (2025)'!F12-'Bach et al. (2025)'!F13)/100 -> 0.1586 | F12: ='Insee (2026)'!S91 -> 0.55033213 | T12: =F12 -> 0.55033213 | U12: =T12 -> 0.55033213
A13: P90-P99 | B13: ='Bach et al. (2025)'!C13-'Bach et al. (2025)'!C15 -> 3404985 | C13: =('Bach et al. (2025)'!F13-'Bach et al. (2025)'!F15)/100 -> 0.2508 | F13: =SUMPRODUCT('Bach et al. (2025)'!AA4:AA12,'Bach et al. (2025)'!I4:I12)/SUM('Bach et al. (2025)'!I4:I12)*1 + 'Insee (2026)'!U91*0 -> 0.54308957 | T13: =F13 -> 0.54308957 | U13: =T13 -> 0.54308957
A14: P99-P99.9 | B14: ='Bach et al. (2025)'!C15 - 'Bach et al. (2025)'!C16 -> 340500 | C14: =('Bach et al. (2025)'!F15-'Bach et al. (2025)'!F16)/100 -> 0.0764 | D14: =('Bach et al. (2025)'!C15*'Bach et al. (2025)'!E15 - 'Bach et al. (2025)'!E16*'Bach et al. (2025)'!C16)/('Bach et al. (2025)'!C15-'Bach et al. (2025)'!C16) -> 279445.99 | E14: ='Bach et al. (2025)'!D15 -> 180000 | F14: =SUMPRODUCT('Bach et al. (2025)'!AA13:AA21,'Bach et al. (2025)'!I13:I21)/SUM('Bach et al. (2025)'!I13:I21) -> 0.56201136 | G14: =(SUMPRODUCT('Bach et al. (2025)'!K13:K21,'Bach et al. (2025)'!I13:I21) + SUMPRODUCT('Bach et al. (2025)'!L13:L21,'Bach et al. (2025)'!I13:I21) + SUMPRODUCT('Bach et al. (2025)'!N13:N21,'Bach et al. (2025)'!I13:I21) + SUMPRODUCT('Bach et al. (2025)'!X13:X21,'Bach et al. (2025)'!I13:I21))/SUM('Bach et al. (2025)'!I13:I21) -> 0.24326656 | H14: 0.13 | I14: =WID!O5 -> 0.031988821 | J14: =WID!O36 -> 0.023686218 | K14: =WID!O$66 -> 0.0054522348 | L14: =H14*G14 -> 0.031624653 | M14: =D14*(1+I14)^9 -> 370999.07 | N14: =E14*(1+J14)^9 -> 222215.43 | O14: =(N14/H14)/1000000 -> 1.7093495 | P14: =M14/(M14-N14) -> 2.4935475 | Q14: =P14*(1-(N14/N15)^(P14-1)) -> 2.2288297 | R14: =MIN(1,MAX((M$22^(-Q14+1)-O15^(-Q14+1))/(O14^(-Q14+1)-O15^(-Q14+1)),0)) -> 0 | S14: =MIN(1,MAX((M$22^(-Q14)-O15^(-Q14))/(O14^(-Q14)-O15^(-Q14)),0))*B14*(1+K14)^9 -> 0 | T14: =F14 -> 0.56201136 | U14: =F14+MAX(0,M$23/H14-G14)*R14 -> 0.56201136 | V14: =(U14-T14)*M14*B14*(1+K14)^9/1000000 -> 0
A15: P99.9-P99.99 | B15: ='Bach et al. (2025)'!C16 - 'Bach et al. (2025)'!C17 -> 34050 | C15: =('Bach et al. (2025)'!F16-'Bach et al. (2025)'!F17)/100 -> 0.0288 | D15: =('Bach et al. (2025)'!C16*'Bach et al. (2025)'!E16 - 'Bach et al. (2025)'!E17*'Bach et al. (2025)'!C17)/('Bach et al. (2025)'!C16-'Bach et al. (2025)'!C17) -> 1052864.3 | E15: ='Bach et al. (2025)'!D16 -> 626000 | F15: =SUMPRODUCT('Bach et al. (2025)'!AA22:AA30, 'Bach et al. (2025)'!I22:I30)/ SUM('Bach et al. (2025)'!I22:I30) -> 0.53664254 | G15: =(SUMPRODUCT('Bach et al. (2025)'!K22:K30,'Bach et al. (2025)'!I22:I30) + SUMPRODUCT('Bach et al. (2025)'!L22:L30,'Bach et al. (2025)'!I22:I30) + SUMPRODUCT('Bach et al. (2025)'!N22:N30,'Bach et al. (2025)'!I22:I30) + SUMPRODUCT('Bach et al. (2025)'!X22:X30,'Bach et al. (2025)'!I22:I30) )/SUM('Bach et al. (2025)'!I22:I30) -> 0.23590774 | H15: 0.108 | I15: =WID!O6 -> 0.051621534 | J15: =WID!O37 -> 0.053136389 | K15: =WID!O$66 -> 0.0054522348 | L15: =H15*G15 -> 0.025478036 | M15: =D15*(1+I15)^9 -> 1656180.4 | N15: =E15*(1+J15)^9 -> 997552.83 | O15: =(N15/H15)/1000000 -> 9.2366003 | P15: =M15/(M15-N15) -> 2.5145932 | Q15: =P15*(1-(N15/N16)^(P15-1)) -> 2.2606245 | R15: =MIN(1,MAX((M$22^(-Q15+1)-O16^(-Q15+1))/(O15^(-Q15+1)-O16^(-Q15+1)),0)) -> 0 | S15: =MIN(1,MAX((M$22^(-Q15)-O16^(-Q15))/(O15^(-Q15)-O16^(-Q15)),0))*B15*(1+K15)^9 -> 0 | T15: =F15 -> 0.53664254 | U15: =F15+MAX(0,M$23/H15-G15)*R15 -> 0.53664254 | V15: =(U15-T15)*M15*B15*(1+K15)^9/1000000 -> 0
A16: P99.99-P99.999 | B16: ='Bach et al. (2025)'!C17 - 'Bach et al. (2025)'!C18 -> 3405 | C16: =('Bach et al. (2025)'!F17-'Bach et al. (2025)'!F18)/100 -> 0.0134 | D16: =('Bach et al. (2025)'!C17*'Bach et al. (2025)'!E17 - 'Bach et al. (2025)'!E18*'Bach et al. (2025)'!C18)/('Bach et al. (2025)'!C17-'Bach et al. (2025)'!C18) -> 4892164.8 | E16: ='Bach et al. (2025)'!D17 -> 2592000 | F16: =SUMPRODUCT('Bach et al. (2025)'!AA31:AA39,'Bach et al. (2025)'!I31:I39)/SUM('Bach et al. (2025)'!I31:I39) -> 0.45859222 | G16: =(SUMPRODUCT('Bach et al. (2025)'!K31:K39,'Bach et al. (2025)'!I31:I39) +SUMPRODUCT('Bach et al. (2025)'!L31:L39,'Bach et al. (2025)'!I31:I39) + SUMPRODUCT('Bach et al. (2025)'!N31:N39,'Bach et al. (2025)'!I31:I39) + + SUMPRODUCT('Bach et al. (2025)'!X31:X39,'Bach et al. (2025)'!I31:I39))/SUM('Bach et al. (2025)'!I31:I39) -> 0.16326935 | H16: 0.083 | I16: =WID!O7 -> 0.067228319 | J16: =WID!O38 -> 0.064060531 | K16: =WID!O$66 -> 0.0054522348 | L16: =H16*G16 -> 0.013551356 | M16: =D16*(1+I16)^9 -> 8786524.8 | N16: =E16*(1+J16)^9 -> 4532439.4 | O16: =(N16/H16)/1000000 -> 54.607704 | P16: =M16/(M16-N16) -> 2.0654321 | Q16: =P16*(1-(N16/N17)^(P16-1)) -> 1.8302845 | R16: =MIN(1,MAX((M$22^(-Q16+1)-O17^(-Q16+1))/(O16^(-Q16+1)-O17^(-Q16+1)),0)) -> 0.52585226 | S16: =MIN(1,MAX((M$22^(-Q16)-O17^(-Q16))/(O16^(-Q16)-O17^(-Q16)),0))*B16*(1+K16)^9 -> 1134.2492 | T16: =F16 -> 0.45859222 | U16: =F16+MAX(0,M$23/H16-G16)*R16 -> 0.49944806 | V16: =(U16-T16)*M16*B16*(1+K16)^9/1000000 -> 1283.6342
A17: P99.999-Billionaires | B17: ='Bach et al. (2025)'!C18 - 'Bach et al. (2025)'!C19 -> 303 | C17: =('Bach et al. (2025)'!F18-'Bach et al. (2025)'!F19)/100 -> 0.0066 | D17: =('Bach et al. (2025)'!C18*'Bach et al. (2025)'!E18 - 'Bach et al. (2025)'!E19*'Bach et al. (2025)'!C19)/('Bach et al. (2025)'!C18-'Bach et al. (2025)'!C19) -> 27015277 | E17: ='Bach et al. (2025)'!D18 -> 14876000 | F17: =AVERAGE('Bach et al. (2025)'!AA40:AA44) -> 0.32722839 | G17: =AVERAGE('Bach et al. (2025)'!K40:K44) + AVERAGE('Bach et al. (2025)'!L40:L44) + AVERAGE('Bach et al. (2025)'!N40:N44) + + AVERAGE('Bach et al. (2025)'!X40:X44) -> 0.073443388 | H17: 0.074 | I17: =WID!O8 -> 0.10834128 | J17: =WID!O39 -> 0.099163812 | K17: =WID!O$66 -> 0.0054522348 | L17: =H17*G17 -> 0.0054348107 | M17: =D17*(1+I17)^9 -> 68182200 | N17: =E17*(1+J17)^9 -> 34837579 | O17: =(N17/H17)/1000000 -> 470.77809 | P17: =M17/(M17-N17) -> 2.0447736 | Q17: =P17*(1-(N17/N18)^(P17-1)) -> 1.5809388 | R17: =MIN(1,MAX((M$22^(-Q17+1)-O18^(-Q17+1))/(O17^(-Q17+1)-O18^(-Q17+1)),0)) -> 1 | S17: =MIN(1,MAX((M$22^(-Q17)-O18^(-Q17))/(O17^(-Q17)-O18^(-Q17)),0))*B17*(1+K17)^9 -> 318.19666 | T17: =F17 -> 0.32722839 | U17: =F17+MAX(0,M$23/H17-G17)*R17 -> 0.52405527 | V17: =(U17-T17)*M17*B17*(1+K17)^9/1000000 -> 4270.2278
A18: Billionaires | B18: ='Bach et al. (2025)'!C19 -> 75 | C18: ='Bach et al. (2025)'!F19/100 -> 0.0131 | D18: ='Bach et al. (2025)'!E19 -> 217289000 | E18: ='Bach et al. (2025)'!D19 -> 61540000 | F18: ='Bach et al. (2025)'!AA45 -> 0.25752107 | G18: ='Bach et al. (2025)'!K45 + 'Bach et al. (2025)'!L45 + 'Bach et al. (2025)'!N45 + 'Bach et al. (2025)'!X45 -> 0.021091068 | H18: 0.07 | I18: =WID!O8 -> 0.10834128 | J18: =WID!O39 -> 0.099163812 | K18: =WID!O$66 -> 0.0054522348 | L18: =H18*G18 -> 0.0014763747 | M18: =D18*(1+I18)^9 -> 5.4840237e+08 | N18: =E18*(1+J18)^9 -> 1.4411835e+08 | O18: =(N18/H18)/1000000 -> 2058.8336 | P18: =M18/(M18-N18) -> 1.356478 | R18: =IF(M$22<=O18, 1, (O18/M$22)^(P18-1)) -> 1 | S18: =IF(M$22<=O18, 1, (O18/M$22)^P18)*B18*(1+K18)^9 -> 78.76155 | T18: 0.26 | U18: =T18+MAX(0,M$23/H18-G18)*R18 -> 0.52462322 | V18: =(U18-T18)*M18*B18*(1+K18)^9/1000000 -> 11429.876
S19: =SUM(S14:S18) -> 1531.2074 | V19: =SUM(V14:V18) -> 16983.738
B20: Sources: INSEE (2024) and Bach et al. (2025). See formulas.
B21: Note: Tax rates from Bach et al. (2025) are corrected for incorporating indirect taxes and contributive SSCs. | L21: Reform Parameters | T21: Summary of revenu estimates
B22: See 'Bach et al. (2025)' sheet. | L22: Threshold | M22: 100 | T22: =+V19 -> 16983.738 | U22: 0.02 | V22: 0.03
L23: Rate | M23: 0.02 | T23: 100 | U23: 16983.738 | V23: 28076.523
T24: 1000 | U24: 13070.687 | V24: 20367.647

Sheet NDL
B2: Data (2016) | H2: Assumptions | L2: Simulations (2025)
A3: Group | B3: Number of units | C3: Income share | D3: Average income | E3: Income threshold | F3: Total tax rate | G3: Individual tax rate | H3: Income / Wealth Ratio | I3: Nominal growth rate (average) | J3: Nominal growth rate (threshold) | K3: Population growth | L3: Current wealth tax rate | M3: Average income | N3: Income threshold | O3: Wealth threshold | P3: Patero coefficient alpha | Q3: Corrected alpha | R3: Share of wealth exposed | S3: Number of units exposed | T3: Current tax rate | U3: Tax rate under reform | V3: Extra fiscal revenues
A4: P0-P10 | B4: ='Bruil et al. (2025)'!J5/5 -> 1333236.8 | C4: ='Bruil et al. (2025)'!$M$5*('Bach et al. (2025)'!F4-'Bach et al. (2025)'!F5)/('Bach et al. (2025)'!$F$4-'Bach et al. (2025)'!$F$9) -> 0.0018948296
A5: P10-P20 | B5: ='Bruil et al. (2025)'!J5/5 -> 1333236.8 | C5: ='Bruil et al. (2025)'!$M$5*('Bach et al. (2025)'!F5-'Bach et al. (2025)'!F6)/('Bach et al. (2025)'!$F$4-'Bach et al. (2025)'!$F$9) -> 0.026527615 | F5: ='Bruil et al. (2025)'!G4 -> 0.50664804 | T5: =F5 -> 0.50664804 | U5: =T5 -> 0.50664804
A6: P20-P30 | B6: ='Bruil et al. (2025)'!J5/5 -> 1333236.8 | C6: ='Bruil et al. (2025)'!$M$5*('Bach et al. (2025)'!F6-'Bach et al. (2025)'!F7)/('Bach et al. (2025)'!$F$4-'Bach et al. (2025)'!$F$9) -> 0.046865452 | F6: ='Bruil et al. (2025)'!G5 -> 0.45769899 | T6: =F6 -> 0.45769899 | U6: =T6 -> 0.45769899
A7: P30-P40 | B7: ='Bruil et al. (2025)'!J5/5 -> 1333236.8 | C7: ='Bruil et al. (2025)'!$M$5*('Bach et al. (2025)'!F7-'Bach et al. (2025)'!F8)/('Bach et al. (2025)'!$F$4-'Bach et al. (2025)'!$F$9) -> 0.061392479 | F7: ='Bruil et al. (2025)'!G6 -> 0.45706849 | T7: =F7 -> 0.45706849 | U7: =T7 -> 0.45706849
A8: P40-P50 | B8: ='Bruil et al. (2025)'!J5/5 -> 1333236.8 | C8: ='Bruil et al. (2025)'!$M$5*('Bach et al. (2025)'!F8-'Bach et al. (2025)'!F9)/('Bach et al. (2025)'!$F$4-'Bach et al. (2025)'!$F$9) -> 0.078319624 | F8: ='Bruil et al. (2025)'!G7 -> 0.46145334 | T8: =F8 -> 0.46145334 | U8: =T8 -> 0.46145334
A9: P50-P60 | B9: ='Bruil et al. (2025)'!J6/4 -> 1333236.8 | C9: ='Bruil et al. (2025)'!$M$6*('Bach et al. (2025)'!F9-'Bach et al. (2025)'!F10)/('Bach et al. (2025)'!$F$9-'Bach et al. (2025)'!$F$13) -> 0.072314046 | F9: ='Bruil et al. (2025)'!G8 -> 0.46669341 | T9: =F9 -> 0.46669341 | U9: =T9 -> 0.46669341
A10: P60-P70 | B10: ='Bruil et al. (2025)'!J6/4 -> 1333236.8 | C10: ='Bruil et al. (2025)'!$M$6*('Bach et al. (2025)'!F10-'Bach et al. (2025)'!F11)/('Bach et al. (2025)'!$F$9-'Bach et al. (2025)'!$F$13) -> 0.089901293 | F10: ='Bruil et al. (2025)'!G9 -> 0.47420146 | T10: =F10 -> 0.47420146 | U10: =T10 -> 0.47420146
A11: P70-P80 | B11: ='Bruil et al. (2025)'!J6/4 -> 1333236.8 | C11: ='Bruil et al. (2025)'!$M$6*('Bach et al. (2025)'!F11-'Bach et al. (2025)'!F12)/('Bach et al. (2025)'!$F$9-'Bach et al. (2025)'!$F$13) -> 0.11495575 | F11: ='Bruil et al. (2025)'!G10 -> 0.48305826 | T11: =F11 -> 0.48305826 | U11: =T11 -> 0.48305826
A12: P80-P90 | B12: ='Bruil et al. (2025)'!J6/4 -> 1333236.8 | C12: ='Bruil et al. (2025)'!$M$6*('Bach et al. (2025)'!F12-'Bach et al. (2025)'!F13)/('Bach et al. (2025)'!$F$9-'Bach et al. (2025)'!$F$13) -> 0.15582891 | F12: ='Bruil et al. (2025)'!G11 -> 0.4862709 | T12: =F12 -> 0.4862709 | U12: =T12 -> 0.4862709
A13: P90-P99 | B13: ='Bruil et al. (2025)'!J7-'Bruil et al. (2025)'!J8 -> 1199913 | C13: ='Bruil et al. (2025)'!M7-'Bruil et al. (2025)'!M8 -> 0.212 | F13: ='Bruil et al. (2025)'!G12 -> 0.43747519 | T13: =F13 -> 0.43747519 | U13: =T13 -> 0.43747519
A14: P99-P99.9 | B14: ='Bruil et al. (2025)'!J8-'Bruil et al. (2025)'!J9 -> 119991 | C14: ='Bruil et al. (2025)'!M8-'Bruil et al. (2025)'!M9 -> 0.08 | D14: =('Bruil et al. (2025)'!L8*'Bruil et al. (2025)'!J8-'Bruil et al. (2025)'!L9*'Bruil et al. (2025)'!J9)/('Bruil et al. (2025)'!J8-'Bruil et al. (2025)'!J9) -> 395560.73 | E14: ='Bruil et al. (2025)'!K8 -> 226162 | F14: ='Bruil et al. (2025)'!G13 -> 0.27181551 | G14: ='Bruil et al. (2025)'!C13 -> 0.11227558 | H14: 0.13 | I14: =WID!O15 -> 0.052374181 | J14: =WID!O46 -> 0.052430928 | K14: =WID!O$68 -> 0.010294291 | L14: =H14*G14 -> 0.014595825 | M14: =D14*(1+I14)^9 -> 626245.8 | N14: =E14*(1+J14)^9 -> 358230.08 | O14: =(N14/H14)/1000000 -> 2.755616 | P14: =M14/(M14-N14) -> 2.336601 | Q14: =P14*(1-(N14/N15)^(P14-1)) -> 1.9986133 | R14: =MIN(1,MAX((M$22^(-Q14+1)-O15^(-Q14+1))/(O14^(-Q14+1)-O15^(-Q14+1)),0)) -> 0 | S14: =MIN(1,MAX((M$22^(-Q14)-O15^(-Q14))/(O14^(-Q14)-O15^(-Q14)),0))*B14*(1+K14)^9 -> 0 | T14: =F14 -> 0.27181551 | U14: =F14+MAX(0,M$23/H14-G14)*R14 -> 0.27181551 | V14: =(U14-T14)*M14*B14*(1+K14)^9/1000000 -> 0
A15: P99.9-P99.99 | B15: ='Bruil et al. (2025)'!J9-'Bruil et al. (2025)'!J10 -> 11999 | C15: ='Bruil et al. (2025)'!M9-'Bruil et al. (2025)'!M10 -> 0.036 | D15: =('Bruil et al. (2025)'!L9*'Bruil et al. (2025)'!J9-'Bruil et al. (2025)'!L10*'Bruil et al. (2025)'!J10)/('Bruil et al. (2025)'!J9-'Bruil et al. (2025)'!J10) -> 1780094.1 | E15: ='Bruil et al. (2025)'!K9 -> 1023879 | F15: ='Bruil et al. (2025)'!G14 -> 0.21413333 | G15: ='Bruil et al. (2025)'!C14 -> 0.061872382 | H15: 0.108 | I15: =WID!O16 -> 0.044324266 | J15: =WID!O47 -> 0.045024033 | K15: =WID!O$68 -> 0.010294291 | L15: =H15*G15 -> 0.0066822173 | M15: =D15*(1+I15)^9 -> 2630033.5 | N15: =E15*(1+J15)^9 -> 1521896.6 | O15: =(N15/H15)/1000000 -> 14.091635 | P15: =M15/(M15-N15) -> 2.3733831 | Q15: =P15*(1-(N15/N16)^(P15-1)) -> 2.0478618 | R15: =MIN(1,MAX((M$22^(-Q15+1)-O16^(-Q15+1))/(O15^(-Q15+1)-O16^(-Q15+1)),0)) -> 0 | S15: =MIN(1,MAX((M$22^(-Q15)-O16^(-Q15))/(O15^(-Q15)-O16^(-Q15)),0))*B15*(1+K15)^9 -> 0 | T15: =F15 -> 0.21413333 | U15: =F15+MAX(0,M$23/H15-G15)*R15 -> 0.21413333 | V15: =(U15-T15)*M15*B15*(1+K15)^9/1000000 -> 0
A16: P99.99-P99.999 | B16: ='Bruil et al. (2025)'!J10-'Bruil et al. (2025)'!J11 -> 1200 | C16: ='Bruil et al. (2025)'!M10-'Bruil et al. (2025)'!M11 -> 0.016 | D16: =('Bruil et al. (2025)'!L10*'Bruil et al. (2025)'!J10-'Bruil et al. (2025)'!L11*'Bruil et al. (2025)'!J11)/('Bruil et al. (2025)'!J10-'Bruil et al. (2025)'!J11) -> 7606596 | E16: ='Bruil et al. (2025)'!K10 -> 4372218 | F16: ='Bruil et al. (2025)'!G15 -> 0.19061302 | G16: ='Bruil et al. (2025)'!C15 -> 0.044620932 | H16: 0.083 | I16: =WID!O17 -> 0.046466517 | J16: =WID!O48 -> 0.044427469 | K16: =WID!O$68 -> 0.010294291 | L16: =H16*G16 -> 0.0037035373 | M16: =D16*(1+I16)^9 -> 11447704 | N16: =E16*(1+J16)^9 -> 6465563.5 | O16: =(N16/H16)/1000000 -> 77.898355 | P16: =M16/(M16-N16) -> 2.2977481 | Q16: =P16*(1-(N16/N17)^(P16-1)) -> 1.9307494 | R16: =MIN(1,MAX((M$22^(-Q16+1)-O17^(-Q16+1))/(O16^(-Q16+1)-O17^(-Q16+1)),0)) -> 0.72666454 | S16: =MIN(1,MAX((M$22^(-Q16)-O17^(-Q16))/(O16^(-Q16)-O17^(-Q16)),0))*B16*(1+K16)^9 -> 784.63366 | T16: =F16 -> 0.19061302 | U16: =F16+MAX(0,M$23/H16-G16)*R16 -> 0.33328846 | V16: =(U16-T16)*M16*B16*(1+K16)^9/1000000 -> 2149.2154
A17: P99.999-Billionaires | B17: ='Bruil et al. (2025)'!J11-'Bruil et al. (2025)'!J12 -> 120 | C17: ='Bruil et al. (2025)'!M11-'Bruil et al. (2025)'!M12 -> 0.006 | D17: =('Bruil et al. (2025)'!L11*'Bruil et al. (2025)'!J11-'Bruil et al. (2025)'!L12*'Bruil et al. (2025)'!J12)/('Bruil et al. (2025)'!J11-'Bruil et al. (2025)'!J12) -> 32324145 | E17: ='Bruil et al. (2025)'!K11 -> 18828918 | F17: ='Bruil et al. (2025)'!G16 -> 0.18179299 | G17: ='Bruil et al. (2025)'!C16 -> 0.02212867 | H17: 0.074 | I17: =WID!O18 -> 0.036261402 | J17: =WID!O49 -> 0.03902733 | K17: =WID!O$68 -> 0.010294291 | L17: =H17*G17 -> 0.0016375216 | M17: =D17*(1+I17)^9 -> 44540074 | N17: =E17*(1+J17)^9 -> 26574684 | O17: =(N17/H17)/1000000 -> 359.11735 | P17: =M17/(M17-N17) -> 2.4792155 | Q17: =P17*(1-(N17/N18)^(P17-1)) -> 2.233169 | R17: =MIN(1,MAX((M$22^(-Q17+1)-O18^(-Q17+1))/(O17^(-Q17+1)-O18^(-Q17+1)),0)) -> 1 | S17: =MIN(1,MAX((M$22^(-Q17)-O18^(-Q17))/(O17^(-Q17)-O18^(-Q17)),0))*B17*(1+K17)^9 -> 131.5868 | T17: =F17 -> 0.18179299 | U17: =F17+MAX(0,M$23/H17-G17)*R17 -> 0.42993459 | V17: =(U17-T17)*M17*B17*(1+K17)^9/1000000 -> 1454.3296
A18: Billionaires | B18: ='Bruil et al. (2025)'!J12 -> 14 | C18: ='Bruil et al. (2025)'!M12 -> 0.003 | D18: ='Bruil et al. (2025)'!L12 -> 111562388 | E18: ='Bruil et al. (2025)'!K12 -> 89761129 | F18: ='Bruil et al. (2025)'!G17 -> 0.16443377 | G18: ='Bruil et al. (2025)'!C17 -> 0.0023009031 | H18: 0.07 | I18: =WID!O18 -> 0.036261402 | J18: =WID!O49 -> 0.03902733 | K18: =WID!O$68 -> 0.010294291 | L18: =H18*G18 -> 0.00016106322 | M18: =D18*(1+I18)^9 -> 1.5372401e+08 | N18: =E18*(1+J18)^9 -> 1.2668671e+08 | O18: =(N18/H18)/1000000 -> 1809.8101 | P18: =M18/(M18-N18) -> 5.685627 | R18: =IF(M$22<=O18, 1, (O18/M$22)^(P18-1)) -> 1 | S18: =IF(M$22<=O18, 1, (O18/M$22)^P18)*B18*(1+K18)^9 -> 15.351794 | T18: 0.26 | U18: =T18+MAX(0,M$23/H18-G18)*R18 -> 0.54341338 | V18: =(U18-T18)*M18*B18*(1+K18)^9/1000000 -> 668.83837
S19: =SUM(S14:S18) -> 931.57226 | V19: =SUM(V14:V18) -> 4272.3834
B20: Source: Bruil et al (2025). See formulas.
B21: Note: For dissagregating income shares within the bottom 50% and the middle 40%, we use the shares observed in France. | L21: Reform Parameters | T21: Summary of revenu estimates
L22: Threshold | M22: 100 | T22: =+V19 -> 4272.3834 | U22: 0.02 | V22: 0.03
L23: Rate | M23: 0.02 | T23: 100 | U23: 4272.3834 | V23: 6720.3525
T24: 1000 | U24: 915.87086 | V24: 1387.5362

Sheet USA
B2: Data (2024) | H2: Assumptions | L2: Simulations (2025)
A3: Group | B3: Number of units | C3: Income share | D3: Average income | E3: Income threshold | F3: Total tax rate | G3: Individual tax rate | H3: Income / Wealth Ratio | I3: Nominal growth rate (average) | J3: Nominal growth rate (threshold) | K3: Population growth | L3: Current wealth tax rate | M3: Average income | N3: Income threshold | O3: Wealth threshold | P3: Patero coefficient alpha | Q3: Corrected alpha | R3: Share of wealth exposed | S3: Number of units exposed | T3: Current tax rate | U3: Tax rate under reform | V3: Extra fiscal revenues
A4: P0-P10 | B4: =SUM('Piketty, Saez, Zucman (2018)'!C4:C13) -> 18271113 | C4: =SUM('Piketty, Saez, Zucman (2018)'!E4:E13) -> 0.0046 | F4: =SUMPRODUCT('Piketty, Saez, Zucman (2018)'!H4:H13, 'Piketty, Saez, Zucman (2018)'!$F4:$F13)/SUM('Piketty, Saez, Zucman (2018)'!$F4:$F13) + R21*SUMPRODUCT('Piketty, Saez, Zucman (2018)'!O4:O13, 'Piketty, Saez, Zucman (2018)'!$F4:$F13)/SUM('Piketty, Saez, Zucman (2018)'!$F4:$F13) -> 0.39046205
A5: P10-P20 | B5: =SUM('Piketty, Saez, Zucman (2018)'!C14:C23) -> 18273171 | C5: =SUM('Piketty, Saez, Zucman (2018)'!E14:E23) -> 0.01312 | F5: =SUMPRODUCT('Piketty, Saez, Zucman (2018)'!H14:H23, 'Piketty, Saez, Zucman (2018)'!$F14:$F23)/SUM('Piketty, Saez, Zucman (2018)'!$F14:$F23) + R21*SUMPRODUCT('Piketty, Saez, Zucman (2018)'!O14:O23, 'Piketty, Saez, Zucman (2018)'!$F14:$F23)/SUM('Piketty, Saez, Zucman (2018)'!$F14:$F23) -> 0.25941116 | T5: =F5 -> 0.25941116 | U5: =T5 -> 0.25941116
A6: P20-P30 | B6: =SUM('Piketty, Saez, Zucman (2018)'!C24:C33) -> 18272267 | C6: =SUM('Piketty, Saez, Zucman (2018)'!E24:E33) -> 0.02089 | F6: =SUMPRODUCT('Piketty, Saez, Zucman (2018)'!H24:H33, 'Piketty, Saez, Zucman (2018)'!$F24:$F33)/SUM('Piketty, Saez, Zucman (2018)'!$F24:$F33) + R21*SUMPRODUCT('Piketty, Saez, Zucman (2018)'!O24:O33, 'Piketty, Saez, Zucman (2018)'!$F24:$F33)/SUM('Piketty, Saez, Zucman (2018)'!$F24:$F33) -> 0.24822442 | T6: =F6 -> 0.24822442 | U6: =T6 -> 0.24822442
A7: P30-P40 | B7: =SUM('Piketty, Saez, Zucman (2018)'!C34:C43) -> 18271128 | C7: =SUM('Piketty, Saez, Zucman (2018)'!E34:E43) -> 0.02933 | F7: =SUMPRODUCT('Piketty, Saez, Zucman (2018)'!H34:H43, 'Piketty, Saez, Zucman (2018)'!$F34:$F43)/SUM('Piketty, Saez, Zucman (2018)'!$F34:$F43) + R21*SUMPRODUCT('Piketty, Saez, Zucman (2018)'!O34:O43, 'Piketty, Saez, Zucman (2018)'!$F34:$F43)/SUM('Piketty, Saez, Zucman (2018)'!$F34:$F43) -> 0.26313325 | T7: =F7 -> 0.26313325 | U7: =T7 -> 0.26313325
A8: P40-P50 | B8: =SUM('Piketty, Saez, Zucman (2018)'!C44:C53) -> 18272260 | C8: =SUM('Piketty, Saez, Zucman (2018)'!E44:E53) -> 0.03921 | F8: =SUMPRODUCT('Piketty, Saez, Zucman (2018)'!H44:H53, 'Piketty, Saez, Zucman (2018)'!$F44:$F53)/SUM('Piketty, Saez, Zucman (2018)'!$F44:$F53) + R21*SUMPRODUCT('Piketty, Saez, Zucman (2018)'!O44:O53, 'Piketty, Saez, Zucman (2018)'!$F44:$F53)/SUM('Piketty, Saez, Zucman (2018)'!$F44:$F53) -> 0.26624154 | T8: =F8 -> 0.26624154 | U8: =T8 -> 0.26624154
A9: P50-P60 | B9: =SUM('Piketty, Saez, Zucman (2018)'!C54:C63) -> 18271308 | C9: =SUM('Piketty, Saez, Zucman (2018)'!E54:E63) -> 0.051059999 | F9: =SUMPRODUCT('Piketty, Saez, Zucman (2018)'!H54:H63, 'Piketty, Saez, Zucman (2018)'!$F54:$F63)/SUM('Piketty, Saez, Zucman (2018)'!$F54:$F63) + R21*SUMPRODUCT('Piketty, Saez, Zucman (2018)'!O54:O63, 'Piketty, Saez, Zucman (2018)'!$F54:$F63)/SUM('Piketty, Saez, Zucman (2018)'!$F54:$F63) -> 0.28002967 | T9: =F9 -> 0.28002967 | U9: =T9 -> 0.28002967
A10: P60-P70 | B10: =SUM('Piketty, Saez, Zucman (2018)'!C64:C73) -> 18273673 | C10: =SUM('Piketty, Saez, Zucman (2018)'!E64:E73) -> 0.07135 | F10: =SUMPRODUCT('Piketty, Saez, Zucman (2018)'!H64:H73, 'Piketty, Saez, Zucman (2018)'!$F64:$F73)/SUM('Piketty, Saez, Zucman (2018)'!$F64:$F73) + R21*SUMPRODUCT('Piketty, Saez, Zucman (2018)'!O64:O73, 'Piketty, Saez, Zucman (2018)'!$F64:$F73)/SUM('Piketty, Saez, Zucman (2018)'!$F64:$F73) -> 0.29269838 | T10: =F10 -> 0.29269838 | U10: =T10 -> 0.29269838
A11: P70-P80 | B11: =SUM('Piketty, Saez, Zucman (2018)'!C74:C83) -> 18271441 | C11: =SUM('Piketty, Saez, Zucman (2018)'!E74:E83) -> 0.10444 | F11: =SUMPRODUCT('Piketty, Saez, Zucman (2018)'!H74:H83, 'Piketty, Saez, Zucman (2018)'!$F74:$F83)/SUM('Piketty, Saez, Zucman (2018)'!$F74:$F83) + R21*SUMPRODUCT('Piketty, Saez, Zucman (2018)'!O74:O83, 'Piketty, Saez, Zucman (2018)'!$F74:$F83)/SUM('Piketty, Saez, Zucman (2018)'!$F74:$F83) -> 0.29686721 | T11: =F11 -> 0.29686721 | U11: =T11 -> 0.29686721
A12: P80-P90 | B12: =SUM('Piketty, Saez, Zucman (2018)'!C84:C93) -> 18272475 | C12: =SUM('Piketty, Saez, Zucman (2018)'!E84:E93) -> 0.15636 | F12: =SUMPRODUCT('Piketty, Saez, Zucman (2018)'!H84:H93, 'Piketty, Saez, Zucman (2018)'!$F84:$F93)/SUM('Piketty, Saez, Zucman (2018)'!$F84:$F93) + R21*SUMPRODUCT('Piketty, Saez, Zucman (2018)'!O84:O93, 'Piketty, Saez, Zucman (2018)'!$F84:$F93)/SUM('Piketty, Saez, Zucman (2018)'!$F84:$F93) -> 0.29981626 | T12: =F12 -> 0.29981626 | U12: =T12 -> 0.29981626
A13: P90-P99 | B13: =SUM('Piketty, Saez, Zucman (2018)'!C94:C102) -> 16445819 | C13: =SUM('Piketty, Saez, Zucman (2018)'!E94:E102) -> 0.28881 | F13: =SUMPRODUCT('Piketty, Saez, Zucman (2018)'!H94:H102, 'Piketty, Saez, Zucman (2018)'!$F94:$F102)/SUM('Piketty, Saez, Zucman (2018)'!$F94:$F102) + R21*SUMPRODUCT('Piketty, Saez, Zucman (2018)'!O94:O102, 'Piketty, Saez, Zucman (2018)'!$F94:$F102)/SUM('Piketty, Saez, Zucman (2018)'!$F94:$F102) -> 0.31978189 | T13: =F13 -> 0.31978189 | U13: =T13 -> 0.31978189
A14: P99-P99.9 | B14: =SUM('Piketty, Saez, Zucman (2018)'!C103:C111) -> 1644714 | C14: =SUM('Piketty, Saez, Zucman (2018)'!E103:E111) -> 0.11222 | D14: =AVERAGE('Piketty, Saez, Zucman (2018)'!$F103:$F111) -> 1652421.3 | E14: ='Piketty, Saez, Zucman (2018)'!D103 -> 979000 | F14: =SUMPRODUCT('Piketty, Saez, Zucman (2018)'!H103:H111, 'Piketty, Saez, Zucman (2018)'!$F103:$F111)/SUM('Piketty, Saez, Zucman (2018)'!$F103:$F111) + R21*SUMPRODUCT('Piketty, Saez, Zucman (2018)'!O103:O111, 'Piketty, Saez, Zucman (2018)'!$F103:$F111)/SUM('Piketty, Saez, Zucman (2018)'!$F103:$F111) -> 0.33559856 | G14: =SUMPRODUCT('Piketty, Saez, Zucman (2018)'!L103:L111, 'Piketty, Saez, Zucman (2018)'!$F103:$F111)/SUM('Piketty, Saez, Zucman (2018)'!$F103:$F111) -> 0.20279507 | H14: 0.13 | I14: =WID!O10 -> 0.053230665 | J14: =WID!O10 -> 0.053230665 | K14: =WID!O$67 -> 0.0092025446 | L14: =H14*G14 -> 0.026363359 | M14: =D14*(1+I14)^1 -> 1740380.8 | N14: =E14*(1+J14) -> 1031112.8 | O14: =(N14/H14)/1000000 -> 7.9316371 | P14: =M14/(M14-N14) -> 2.4537704 | Q14: =P14*(1-(N14/N15)^(P14-1)) -> 2.1727892 | R14: =MIN(1,MAX((M$22^(-Q14+1)-O15^(-Q14+1))/(O14^(-Q14+1)-O15^(-Q14+1)),0)) -> 0 | S14: =MIN(1,MAX((M$22^(-Q14)-O15^(-Q14))/(O14^(-Q14)-O15^(-Q14)),0))*B14*(1+K14)^1 -> 0 | T14: =F14 -> 0.33559856 | U14: =F14+MAX(0,M$23/H14-G14)*R14 -> 0.33559856 | V14: =(U14-T14)*M14*B14*(1+K14)/1000000 -> 0
A15: P99.9-P99.99 | B15: =SUM('Piketty, Saez, Zucman (2018)'!C112:C120) -> 164455 | C15: =SUM('Piketty, Saez, Zucman (2018)'!E112:E120) -> 0.053910001 | D15: =AVERAGE('Piketty, Saez, Zucman (2018)'!$F112:$F120) -> 7936218.6 | E15: ='Piketty, Saez, Zucman (2018)'!D112 -> 4280000 | F15: =SUMPRODUCT('Piketty, Saez, Zucman (2018)'!H112:H120, 'Piketty, Saez, Zucman (2018)'!$F112:$F120)/SUM('Piketty, Saez, Zucman (2018)'!$F112:$F120) + R21*SUMPRODUCT('Piketty, Saez, Zucman (2018)'!O112:O120, 'Piketty, Saez, Zucman (2018)'!$F112:$F120)/SUM('Piketty, Saez, Zucman (2018)'!$F112:$F120) -> 0.37579076 | G15: =SUMPRODUCT('Piketty, Saez, Zucman (2018)'!L112:L120, 'Piketty, Saez, Zucman (2018)'!$F112:$F120)/SUM('Piketty, Saez, Zucman (2018)'!$F112:$F120) -> 0.23315599 | H15: 0.108 | I15: =WID!O11 -> 0.069676856 | J15: =WID!O11 -> 0.069676856 | K15: =WID!O$67 -> 0.0092025446 | L15: =H15*G15 -> 0.025180847 | M15: =D15*(1+I15)^1 -> 8489189.3 | N15: =E15*(1+J15) -> 4578216.9 | O15: =(N15/H15)/1000000 -> 42.390898 | P15: =M15/(M15-N15) -> 2.1706084 | Q15: =P15*(1-(N15/N16)^(P15-1)) -> 1.8692501 | R15: =MIN(1,MAX((M$22^(-Q15+1)-O16^(-Q15+1))/(O15^(-Q15+1)-O16^(-Q15+1)),0)) -> 0.35601799 | S15: =MIN(1,MAX((M$22^(-Q15)-O16^(-Q15))/(O15^(-Q15)-O16^(-Q15)),0))*B15*(1+K15)^1 -> 29809.439 | T15: =F15 -> 0.37579076 | U15: =F15+MAX(0,M$23/H15-G15)*R15 -> 0.37579076 | V15: =(U15-T15)*M15*B15*(1+K15)/1000000 -> 0
A16: P99.99-P99.999 | B16: =SUM('Piketty, Saez, Zucman (2018)'!C121:C129) -> 16442 | C16: =SUM('Piketty, Saez, Zucman (2018)'!E121:E129) -> 0.02879 | D16: =AVERAGE('Piketty, Saez, Zucman (2018)'!$F121:$F129) -> 42405660 | E16: ='Piketty, Saez, Zucman (2018)'!D121 -> 22800000 | F16: =SUMPRODUCT('Piketty, Saez, Zucman (2018)'!H121:H129, 'Piketty, Saez, Zucman (2018)'!$F121:$F129)/SUM('Piketty, Saez, Zucman (2018)'!$F121:$F129) + R21*SUMPRODUCT('Piketty, Saez, Zucman (2018)'!O121:O129, 'Piketty, Saez, Zucman (2018)'!$F121:$F129)/SUM('Piketty, Saez, Zucman (2018)'!$F121:$F129) -> 0.35651367 | G16: =SUMPRODUCT('Piketty, Saez, Zucman (2018)'!L121:L129, 'Piketty, Saez, Zucman (2018)'!$F121:$F129)/SUM('Piketty, Saez, Zucman (2018)'!$F121:$F129) -> 0.20636722 | H16: 0.083 | I16: =WID!O12 -> 0.084639076 | J16: =WID!O12 -> 0.084639076 | K16: =WID!O$67 -> 0.0092025446 | L16: =H16*G16 -> 0.017128479 | M16: =D16*(1+I16)^1 -> 45994835 | N16: =E16*(1+J16) -> 24729771 | O16: =(N16/H16)/1000000 -> 297.94905 | P16: =M16/(M16-N16) -> 2.1629295 | Q16: =P16*(1-(N16/N17)^(P16-1)) -> 1.8546145 | R16: =MIN(1,MAX((M$22^(-Q16+1)-O17^(-Q16+1))/(O16^(-Q16+1)-O17^(-Q16+1)),0)) -> 1 | S16: =MIN(1,MAX((M$22^(-Q16)-O17^(-Q16))/(O16^(-Q16)-O17^(-Q16)),0))*B16*(1+K16)^1 -> 16593.308 | T16: =F16 -> 0.35651367 | U16: =F16+MAX(0,M$23/H16-G16)*R16 -> 0.39111031 | V16: =(U16-T16)*M16*B16*(1+K16)/1000000 -> 26404.378
A17: P99.999-Billionaires | B17: ='Piketty, Saez, Zucman (2018)'!C130 -> 1431 | C17: ='Piketty, Saez, Zucman (2018)'!E130 -> 0.00985 | D17: ='Piketty, Saez, Zucman (2018)'!F130 -> 166643920 | E17: ='Piketty, Saez, Zucman (2018)'!D130 -> 119000000 | F17: ='Piketty, Saez, Zucman (2018)'!H130 + R21*'Piketty, Saez, Zucman (2018)'!O130 -> 0.29605398 | G17: ='Piketty, Saez, Zucman (2018)'!L130 -> 0.13085756 | H17: 0.074 | I17: =WID!O13 -> 0.10965318 | J17: =WID!O13 -> 0.10965318 | K17: =WID!O$67 -> 0.0092025446 | L17: =H17*G17 -> 0.0096834592 | M17: =D17*(1+I17)^1 -> 1.8491696e+08 | N17: =E17*(1+J17) -> 1.3204873e+08 | O17: =(N17/H17)/1000000 -> 1784.4423 | P17: =M17/(M17-N17) -> 3.4976954 | Q17: =P17*(1-(N17/N18)^(P17-1)) -> -0.30326201 | R17: =MIN(1,MAX((M$22^(-Q17+1)-O18^(-Q17+1))/(O17^(-Q17+1)-O18^(-Q17+1)),0)) -> 1 | S17: =MIN(1,MAX((M$22^(-Q17)-O18^(-Q17))/(O17^(-Q17)-O18^(-Q17)),0))*B17*(1+K17)^1 -> 1444.1688 | T17: =F17 -> 0.29605398 | U17: =F17+MAX(0,M$23/H17-G17)*R17 -> 0.43546669 | V17: =(U17-T17)*M17*B17*(1+K17)/1000000 -> 37230.347
A18: Billionaires | B18: ='Piketty, Saez, Zucman (2018)'!C131 -> 411 | C18: =D18*B18/(D14*B14/C14) -> 0.0067196797 | D18: ='Balkir et al. (2025)'!D10 -> 3.9595668e+08 | E18: =D18/3.44 -> 1.1510368e+08 | F18: ='Balkir et al. (2025)'!F10 -> 0.27186661 | G18: ='Balkir et al. (2025)'!G10*('Piketty, Saez, Zucman (2018)'!L130)/('Piketty, Saez, Zucman (2018)'!L130+'Piketty, Saez, Zucman (2018)'!K130) -> 0.12347621 | H18: 0.049 | I18: =WID!O13 -> 0.10965318 | J18: =WID!O13 -> 0.10965318 | K18: =WID!O$67 -> 0.0092025446 | L18: =H18*G18 -> 0.0060503341 | M18: =D18*(1+I18)^1 -> 4.3937459e+08 | N18: =E18*(1+J18) -> 1.2772517e+08 | O18: =(N18/H18)/1000000 -> 2606.6361 | P18: =M18/(M18-N18) -> 1.4098361 | R18: =IF(M$22<=O18, 1, (O18/M$22)^(P18-1)) -> 1 | S18: =IF(M$22<=O18, 1, (O18/M$22)^P18)*B18*(1+K18)^1 -> 414.78225 | T18: 0.26 | U18: =T18+MAX(0,M$23/H18-G18)*R18 -> 0.54468706 | V18: =(U18-T18)*M18*B18*(1+K18)/1000000 -> 51882.73
S19: =SUM(S14:S18) -> 48261.698 | V19: =SUM(V14:V18) -> 115517.45
B20: Sources: US DINA files for 2024 (PSZ, 2018) and Balkir et al. (2025). See formulas.
B21: Note: For computing income threshold for the billionnaires group, we apply the Pareto coefficient b = 3,44 from Saez & Zucman (2020). | L21: Reform Parameters | O21: Include health premiums in total taxes | R21: 0 | T21: Summary of revenu estimates
B22: See SaezZucman2020JEPData.xlsx, sheet DataF1(Forbes). | L22: Threshold | M22: 100 | T22: =+V19 -> 115517.45 | U22: 0.02 | V22: 0.03
L23: Rate | M23: 0.02 | T23: 100 | U23: 115517.45 | V23: 303133.47
T24: 1000 | U24: 93787.937 | V24: 183348.85

Sheet BRA
B2: Data (2019) | H2: Assumptions | L2: Simulations (2025)
A3: Group | B3: Number of units | C3: Income share | D3: Average income | E3: Income threshold | F3: Total tax rate | G3: Individual tax rate | H3: Income / Wealth Ratio | I3: Nominal growth rate (average) | J3: Nominal growth rate (threshold) | K3: Population growth | L3: Current wealth tax rate | M3: Average income | N3: Income threshold | O3: Wealth threshold | P3: Patero coefficient alpha | Q3: Corrected alpha | R3: Share of wealth exposed | S3: Number of units exposed | T3: Current tax rate | U3: Tax rate under reform | V3: Extra fiscal revenues
A4: P0-P10 | B4: ='Palomo et al. (2025)'!L6-'Palomo et al. (2025)'!L7 -> 15175032 | C4: ='Palomo et al. (2025)'!Q4-'Palomo et al. (2025)'!Q5 -> 0.0015
A5: P10-P20 | B5: ='Palomo et al. (2025)'!L6-'Palomo et al. (2025)'!L7 -> 15175032 | C5: =('Palomo et al. (2025)'!Q5-'Palomo et al. (2025)'!Q6)*('Bach et al. (2025)'!F5-'Bach et al. (2025)'!F6)/('Bach et al. (2025)'!F5-'Bach et al. (2025)'!F7) -> 0.012525374 | F5: ='Palomo et al. (2025)'!C5 -> 0.48921796 | T5: =F5 -> 0.48921796 | U5: =T5 -> 0.48921796
A6: P20-P30 | B6: ='Palomo et al. (2025)'!L6-'Palomo et al. (2025)'!L7 -> 15175032 | C6: =('Palomo et al. (2025)'!Q5-'Palomo et al. (2025)'!Q6)*('Bach et al. (2025)'!F6-'Bach et al. (2025)'!F7)/('Bach et al. (2025)'!F5-'Bach et al. (2025)'!F7) -> 0.02212816 | F6: ='Palomo et al. (2025)'!C5 -> 0.48921796 | T6: =F6 -> 0.48921796 | U6: =T6 -> 0.48921796
A7: P30-P40 | B7: ='Palomo et al. (2025)'!L6-'Palomo et al. (2025)'!L7 -> 15175032 | C7: ='Palomo et al. (2025)'!Q6-'Palomo et al. (2025)'!Q7 -> 0.034106318 | F7: ='Palomo et al. (2025)'!C6 -> 0.4809789 | T7: =F7 -> 0.4809789 | U7: =T7 -> 0.4809789
A8: P40-P50 | B8: ='Palomo et al. (2025)'!L7-'Palomo et al. (2025)'!L8 -> 15175032 | C8: ='Palomo et al. (2025)'!Q7-'Palomo et al. (2025)'!Q8 -> 0.041189 | F8: ='Palomo et al. (2025)'!C7 -> 0.44749116 | T8: =F8 -> 0.44749116 | U8: =T8 -> 0.44749116
A9: P50-P60 | B9: ='Palomo et al. (2025)'!L8-'Palomo et al. (2025)'!L9 -> 15175032 | C9: ='Palomo et al. (2025)'!Q8-'Palomo et al. (2025)'!Q9 -> 0.049900362 | F9: ='Palomo et al. (2025)'!C8 -> 0.46344125 | T9: =F9 -> 0.46344125 | U9: =T9 -> 0.46344125
A10: P60-P70 | B10: ='Palomo et al. (2025)'!L9-'Palomo et al. (2025)'!L10 -> 15175032 | C10: ='Palomo et al. (2025)'!Q9-'Palomo et al. (2025)'!Q10 -> 0.062538191 | F10: ='Palomo et al. (2025)'!C9 -> 0.46875623 | T10: =F10 -> 0.46875623 | U10: =T10 -> 0.46875623
A11: P70-P80 | B11: ='Palomo et al. (2025)'!L10-'Palomo et al. (2025)'!L11 -> 15687814 | C11: ='Palomo et al. (2025)'!Q10-'Palomo et al. (2025)'!Q11 -> 0.056502347 | F11: ='Palomo et al. (2025)'!C10 -> 0.4378783 | T11: =F11 -> 0.4378783 | U11: =T11 -> 0.4378783
A12: P80-P90 | B12: ='Palomo et al. (2025)'!L11-'Palomo et al. (2025)'!L12 -> 14918641 | C12: ='Palomo et al. (2025)'!Q11-'Palomo et al. (2025)'!Q12 -> 0.13112195 | F12: ='Palomo et al. (2025)'!C11 -> 0.49957817 | T12: =F12 -> 0.49957817 | U12: =T12 -> 0.49957817
A13: P90-P99 | B13: ='Palomo et al. (2025)'!L12-'Palomo et al. (2025)'!L14 -> 13426770 | C13: ='Palomo et al. (2025)'!Q12-'Palomo et al. (2025)'!Q14 -> 0.33229163 | F13: =('Palomo et al. (2025)'!C12*('Palomo et al. (2025)'!Q12-'Palomo et al. (2025)'!Q13)+'Palomo et al. (2025)'!C13*('Palomo et al. (2025)'!Q13-'Palomo et al. (2025)'!Q14))/('Palomo et al. (2025)'!Q12-'Palomo et al. (2025)'!Q14) -> 0.4539918 | T13: =F13 -> 0.4539918 | U13: =T13 -> 0.4539918
A14: P99-P99.9 | B14: ='Palomo et al. (2025)'!L14-'Palomo et al. (2025)'!L15 -> 1342683 | C14: ='Palomo et al. (2025)'!Q14-'Palomo et al. (2025)'!Q15 -> 0.13925629 | D14: =('Palomo et al. (2025)'!L14*'Palomo et al. (2025)'!P14-'Palomo et al. (2025)'!L15*'Palomo et al. (2025)'!P15)/('Palomo et al. (2025)'!L14-'Palomo et al. (2025)'!L15) -> 150587.81 | E14: ='Palomo et al. (2025)'!O14 -> 92934.491 | F14: ='Palomo et al. (2025)'!C14 -> 0.30034455 | G14: ='Palomo et al. (2025)'!F14 + 'Palomo et al. (2025)'!H14 -> 0.0954156 | H14: 0.13 | I14: =WID!O20 -> 0.1131934 | J14: =WID!O51 -> 0.10086835 | K14: =WID!O$69 -> 0.010179449 | L14: =H14*G14 -> 0.012404028 | M14: =D14*(1+I14)^6 -> 286558.67 | N14: =E14*(1+J14)^6 -> 165420.46 | O14: =(N14/H14)/1000000 -> 1.2724651 | P14: =M14/(M14-N14) -> 2.3655515 | Q14: =P14*(1-(N14/N15)^(P14-1)) -> 1.9824501 | R14: =MIN(1,MAX((M$22^(-Q14+1)-O15^(-Q14+1))/(O14^(-Q14+1)-O15^(-Q14+1)),0)) -> 0 | S14: =MIN(1,MAX((M$22^(-Q14)-O15^(-Q14))/(O14^(-Q14)-O15^(-Q14)),0))*B14*(1+K14)^6 -> 0 | T14: =F14 -> 0.30034455 | U14: =F14+MAX(0,M$23/H14-G14)*R14 -> 0.30034455 | V14: =(U14-T14)*M14*B14*(1+K14)^6/1000000 -> 0
A15: P99.9-P99.99 | B15: ='Palomo et al. (2025)'!L15-'Palomo et al. (2025)'!L16 -> 134265 | C15: ='Palomo et al. (2025)'!Q15-'Palomo et al. (2025)'!Q16 -> 0.058412486 | D15: =('Palomo et al. (2025)'!L15*'Palomo et al. (2025)'!P15-'Palomo et al. (2025)'!L16*'Palomo et al. (2025)'!P16)/('Palomo et al. (2025)'!L15-'Palomo et al. (2025)'!L16) -> 631671.64 | E15: ='Palomo et al. (2025)'!O15 -> 352926.3 | F15: ='Palomo et al. (2025)'!C15 -> 0.22436049 | G15: ='Palomo et al. (2025)'!F15 + 'Palomo et al. (2025)'!H15 -> 0.04854842 | H15: 0.108 | I15: =WID!O21 -> 0.071989851 | J15: =WID!O52 -> 0.10064308 | K15: =WID!O$69 -> 0.010179449 | L15: =H15*G15 -> 0.0052432294 | M15: =D15*(1+I15)^6 -> 958595.58 | N15: =E15*(1+J15)^6 -> 627426.82 | O15: =(N15/H15)/1000000 -> 5.8095076 | P15: =M15/(M15-N15) -> 2.8945833 | Q15: =P15*(1-(N15/N16)^(P15-1)) -> 2.6814926 | R15: =MIN(1,MAX((M$22^(-Q15+1)-O16^(-Q15+1))/(O15^(-Q15+1)-O16^(-Q15+1)),0)) -> 0 | S15: =MIN(1,MAX((M$22^(-Q15)-O16^(-Q15))/(O15^(-Q15)-O16^(-Q15)),0))*B15*(1+K15)^6 -> 0 | T15: =F15 -> 0.22436049 | U15: =F15+MAX(0,M$23/H15-G15)*R15 -> 0.22436049 | V15: =(U15-T15)*M15*B15*(1+K15)^6/1000000 -> 0
A16: P99.99-P99.999 | B16: ='Palomo et al. (2025)'!L16-'Palomo et al. (2025)'!L17 -> 13430 | C16: ='Palomo et al. (2025)'!Q16-'Palomo et al. (2025)'!Q17 -> 0.030000273 | D16: =('Palomo et al. (2025)'!L16*'Palomo et al. (2025)'!P16-'Palomo et al. (2025)'!L17*'Palomo et al. (2025)'!P17)/('Palomo et al. (2025)'!L16-'Palomo et al. (2025)'!L17) -> 3243379 | E16: ='Palomo et al. (2025)'!O16 -> 1737934.2 | F16: ='Palomo et al. (2025)'!C16 -> 0.21458076 | G16: ='Palomo et al. (2025)'!F16 + 'Palomo et al. (2025)'!H16 -> 0.03369216 | H16: 0.083 | I16: =WID!O22 -> 0.054629983 | J16: =WID!O53 -> 0.061517047 | K16: =WID!O$69 -> 0.010179449 | L16: =H16*G16 -> 0.0027964493 | M16: =D16*(1+I16)^6 -> 4462707.1 | N16: =E16*(1+J16)^6 -> 2486538.4 | O16: =(N16/H16)/1000000 -> 29.958295 | P16: =M16/(M16-N16) -> 2.2582623 | Q16: =P16*(1-(N16/N17)^(P16-1)) -> 1.960451 | R16: =MIN(1,MAX((M$22^(-Q16+1)-O17^(-Q16+1))/(O16^(-Q16+1)-O17^(-Q16+1)),0)) -> 0 | S16: =MIN(1,MAX((M$22^(-Q16)-O17^(-Q16))/(O16^(-Q16)-O17^(-Q16)),0))*B16*(1+K16)^6 -> 0 | T16: =F16 -> 0.21458076 | U16: =F16+MAX(0,M$23/H16-G16)*R16 -> 0.21458076 | V16: =(U16-T16)*M16*B16*(1+K16)^6/1000000 -> 0
A17: P99.999-Billionaires | B17: ='Palomo et al. (2025)'!L17-'Palomo et al. (2025)'!L18 -> 1340 | C17: ='Palomo et al. (2025)'!Q17-'Palomo et al. (2025)'!Q18 -> 0.015756808 | D17: =('Palomo et al. (2025)'!L17*'Palomo et al. (2025)'!P17-'Palomo et al. (2025)'!L18*'Palomo et al. (2025)'!P18)/('Palomo et al. (2025)'!L17-'Palomo et al. (2025)'!L18) -> 17073083 | E17: ='Palomo et al. (2025)'!O17 -> 9018191.6 | F17: ='Palomo et al. (2025)'!C17 -> 0.19708729 | G17: ='Palomo et al. (2025)'!F17 + 'Palomo et al. (2025)'!H17 -> 0.0204606 | H17: 0.074 | I17: =WID!O23 -> 0.055413566 | J17: =WID!O54 -> 0.055083278 | K17: =WID!O$69 -> 0.010179449 | L17: =H17*G17 -> 0.0015140844 | M17: =D17*(1+I17)^6 -> 23596521 | N17: =E17*(1+J17)^6 -> 12440559 | O17: =(N17/H17)/1000000 -> 168.11566 | P17: =M17/(M17-N17) -> 2.1151489 | Q17: =P17*(1-(N17/N18)^(P17-1)) -> 1.7987791 | R17: =MIN(1,MAX((M$22^(-Q17+1)-O18^(-Q17+1))/(O17^(-Q17+1)-O18^(-Q17+1)),0)) -> 0 | S17: =MIN(1,MAX((M$22^(-Q17)-O18^(-Q17))/(O17^(-Q17)-O18^(-Q17)),0))*B17*(1+K17)^6 -> 0 | T17: =F17 -> 0.19708729 | U17: =F17+MAX(0,M$23/H17-G17)*R17 -> 0.19708729 | V17: =(U17-T17)*M17*B17*(1+K17)^6/1000000 -> 0
A18: Billionaires | B18: ='Palomo et al. (2025)'!L18 -> 152 | C18: ='Palomo et al. (2025)'!Q18 -> 0.012770815 | D18: ='Palomo et al. (2025)'!P18 -> 1.219898e+08 | E18: ='Palomo et al. (2025)'!O18 -> 49552064 | F18: ='Palomo et al. (2025)'!C17 -> 0.19708729 | G18: ='Palomo et al. (2025)'!F17 + 'Palomo et al. (2025)'!H17 -> 0.0204606 | H18: 0.08 | I18: =WID!O23 -> 0.055413566 | J18: =WID!O54 -> 0.055083278 | K18: =WID!O$69 -> 0.010179449 | L18: =H18*G18 -> 0.001636848 | M18: =D18*(1+I18)^6 -> 1.6860078e+08 | N18: =E18*(1+J18)^6 -> 68356873 | O18: =(N18/H18)/1000000 -> 854.46091 | P18: =M18/(M18-N18) -> 1.6819055 | R18: =IF(M$22<=O18, 1, (O18/M$22)^(P18-1)) -> 0.8982982 | S18: =IF(M$22<=O18, 1, (O18/M$22)^P18)*B18*(1+K18)^6 -> 123.97882 | T18: 0.26 | U18: =T18+MAX(0,M$23/H18-G18)*R18 -> 0.46619483 | V18: =(U18-T18)*M18*B18*(1+K18)^6/1000000 -> 5615.2889
S19: =SUM(S14:S18) -> 123.97882 | V19: =SUM(V14:V18) -> 5615.2889
B20: Source: Palomo et al. (2025). See formulas.
L21: Reform Parameters | T21: Summary of revenu estimates
L22: Threshold | M22: 1000 | T22: =V19 -> 5615.2889 | U22: 0.02 | V22: 0.03
L23: Rate | M23: 0.02 | T23: 100 | U23: 16658.255 | V23: 25773.375
T24: 1000 | U24: 5615.2889 | V24: 8673.2001

Sheet ITA
B2: Data (2015) | H2: Assumptions | L2: Simulations (2025)
A3: Group | B3: Number of units | C3: Income share | D3: Average income | E3: Income threshold | F3: Total tax rate | G3: Individual tax rate | H3: Income / Wealth Ratio | I3: Nominal growth rate (average) | J3: Nominal growth rate (threshold) | K3: Population growth | L3: Current wealth tax rate | M3: Average income | N3: Income threshold | O3: Wealth threshold | P3: Patero coefficient alpha | Q3: Corrected alpha | R3: Share of wealth exposed | S3: Number of units exposed | T3: Current tax rate | U3: Tax rate under reform | V3: Extra fiscal revenues
A4: P0-P10 | B4: ='Guzzardi et al. (2024)'!C23 -> 5069945 | C4: =('Guzzardi et al. (2024)'!F$21+'Guzzardi et al. (2024)'!F$22)*('Bach et al. (2025)'!F4-'Bach et al. (2025)'!F5)/('Bach et al. (2025)'!F$4-'Bach et al. (2025)'!F$9) -> 0.0014365452
A5: P10-P20 | B5: ='Guzzardi et al. (2024)'!C23 -> 5069945 | C5: =('Guzzardi et al. (2024)'!F$21+'Guzzardi et al. (2024)'!F$22)*('Bach et al. (2025)'!F5-'Bach et al. (2025)'!F6)/('Bach et al. (2025)'!F$4-'Bach et al. (2025)'!F$9) -> 0.020111633 | F5: ='Guzzardi et al. (2024)'!C4 -> 0.42 | T5: =F5 -> 0.42 | U5: =T5 -> 0.42
A6: P20-P30 | B6: ='Guzzardi et al. (2024)'!C23 -> 5069945 | C6: =('Guzzardi et al. (2024)'!F$21+'Guzzardi et al. (2024)'!F$22)*('Bach et al. (2025)'!F6-'Bach et al. (2025)'!F7)/('Bach et al. (2025)'!F$4-'Bach et al. (2025)'!F$9) -> 0.035530552 | F6: ='Guzzardi et al. (2024)'!C4 -> 0.42 | T6: =F6 -> 0.42 | U6: =T6 -> 0.42
A7: P30-P40 | B7: ='Guzzardi et al. (2024)'!C23 -> 5069945 | C7: =('Guzzardi et al. (2024)'!F$21+'Guzzardi et al. (2024)'!F$22)*('Bach et al. (2025)'!F7-'Bach et al. (2025)'!F8)/('Bach et al. (2025)'!F$4-'Bach et al. (2025)'!F$9) -> 0.046544066 | F7: ='Guzzardi et al. (2024)'!C4 -> 0.42 | T7: =F7 -> 0.42 | U7: =T7 -> 0.42
A8: P40-P50 | B8: ='Guzzardi et al. (2024)'!C23 -> 5069945 | C8: =('Guzzardi et al. (2024)'!F$21+'Guzzardi et al. (2024)'!F$22)*('Bach et al. (2025)'!F8-'Bach et al. (2025)'!F9)/('Bach et al. (2025)'!F$4-'Bach et al. (2025)'!F$9) -> 0.059377203 | F8: ='Guzzardi et al. (2024)'!C4 -> 0.42 | T8: =F8 -> 0.42 | U8: =T8 -> 0.42
A9: P50-P60 | B9: ='Guzzardi et al. (2024)'!C23 -> 5069945 | C9: ='Guzzardi et al. (2024)'!F23 -> 0.086 | F9: ='Guzzardi et al. (2024)'!C5 -> 0.43 | T9: =F9 -> 0.43 | U9: =T9 -> 0.43
A10: P60-P70 | B10: ='Guzzardi et al. (2024)'!C23 -> 5069945 | C10: ='Guzzardi et al. (2024)'!F24 -> 0.105 | F10: ='Guzzardi et al. (2024)'!C6 -> 0.45 | T10: =F10 -> 0.45 | U10: =T10 -> 0.45
A11: P70-P80 | B11: ='Guzzardi et al. (2024)'!C23 -> 5069945 | C11: ='Guzzardi et al. (2024)'!F25 -> 0.129 | F11: ='Guzzardi et al. (2024)'!C7 -> 0.47 | T11: =F11 -> 0.47 | U11: =T11 -> 0.47
A12: P80-P90 | B12: ='Guzzardi et al. (2024)'!C23 -> 5069945 | C12: ='Guzzardi et al. (2024)'!F26 -> 0.164 | F12: ='Guzzardi et al. (2024)'!C8 -> 0.49 | T12: =F12 -> 0.49 | U12: =T12 -> 0.49
A13: P90-P99 | B13: ='Guzzardi et al. (2024)'!C27-'Guzzardi et al. (2024)'!C29 -> 4562951 | C13: ='Guzzardi et al. (2024)'!F27 -'Guzzardi et al. (2024)'!F29 -> 0.252 | F13: ='Guzzardi et al. (2024)'!C9 -> 0.5 | T13: =F13 -> 0.5 | U13: =T13 -> 0.5
A14: P99-P99.9 | B14: ='Guzzardi et al. (2024)'!C29-'Guzzardi et al. (2024)'!C30 -> 456295 | C14: ='Guzzardi et al. (2024)'!F29 -'Guzzardi et al. (2024)'!F30 -> 0.073 | D14: =('Guzzardi et al. (2024)'!C29*'Guzzardi et al. (2024)'!E29-'Guzzardi et al. (2024)'!C30*'Guzzardi et al. (2024)'!E30)/('Guzzardi et al. (2024)'!C29-'Guzzardi et al. (2024)'!C30) -> 212338.53 | E14: ='Guzzardi et al. (2024)'!D29 -> 147733 | F14: ='Guzzardi et al. (2024)'!C10 -> 0.43 | G14: ='Guzzardi et al. (2024)'!D10 -> 0.25 | H14: 0.13 | I14: =WID!O25 -> 0.039529547 | J14: =WID!O56 -> 0.035268475 | K14: =WID!O$70 -> -8.4327136e-05 | L14: =H14*G14 -> 0.0325 | M14: =D14*(1+I14)^10 -> 312893.96 | N14: =E14*(1+J14)^10 -> 208933.18 | O14: =(N14/H14)/1000000 -> 1.6071783 | P14: =M14/(M14-N14) -> 3.0097307 | Q14: =P14*(1-(N14/N15)^(P14-1)) -> 2.6588892 | R14: =MIN(1,MAX((M$22^(-Q14+1)-O15^(-Q14+1))/(O14^(-Q14+1)-O15^(-Q14+1)),0)) -> 0 | S14: =MIN(1,MAX((M$22^(-Q14)-O15^(-Q14))/(O14^(-Q14)-O15^(-Q14)),0))*B14*(1+K14)^6 -> 0 | T14: =F14 -> 0.43 | U14: =F14+MAX(0,M$23/H14-G14)*R14 -> 0.43 | V14: =(U14-T14)*M14*B14*(1+K14)^10/1000000 -> 0
A15: P99.9-P99.99 | B15: ='Guzzardi et al. (2024)'!C30*0.9 -> 45629.1 | C15: =(B15*D15)/(D$14*B$14/C$14) -> 0.028490774 | D15: =('Guzzardi et al. (2024)'!E30*SUM(B15:B18)-B16*D16-B17*D17-B18*D18)/B15 -> 828731.79 | E15: =D15/'Guzzardi et al. (2024)'!G$30 -> 351780.3 | F15: ='Guzzardi et al. (2024)'!C11 -> 0.36 | G15: ='Guzzardi et al. (2024)'!D11 -> 0.15 | H15: 0.108 | I15: =WID!O26 -> 0.060947379 | J15: =WID!O57 -> 0.056375828 | K15: =WID!O$70 -> -8.4327136e-05 | L15: =H15*G15 -> 0.0162 | M15: =D15*(1+I15)^10 -> 1497450.4 | N15: =E15*(1+J15)^10 -> 608773.95 | O15: =(N15/H15)/1000000 -> 5.6367959 | P15: =M15/(M15-N15) -> 1.6850344 | Q15: =P15*(1-(N15/N16)^(P15-1)) -> 1.0456869 | R15: =MIN(1,MAX((M$22^(-Q15+1)-O16^(-Q15+1))/(O15^(-Q15+1)-O16^(-Q15+1)),0)) -> 0 | S15: =MIN(1,MAX((M$22^(-Q15)-O16^(-Q15))/(O15^(-Q15)-O16^(-Q15)),0))*B15*(1+K15)^6 -> 0 | T15: =F15 -> 0.36 | U15: =F15+MAX(0,M$23/H15-G15)*R15 -> 0.36 | V15: =(U15-T15)*M15*B15*(1+K15)^10/1000000 -> 0
A16: P99.99-P99.999 | B16: ='Guzzardi et al. (2024)'!C30*0.09 -> 4562.91 | C16: =(B16*D16)/(D$14*B$14/C$14) -> 0.010738936 | D16: =(('Guzzardi et al. (2024)'!E30*(SUM(B15:B18)/SUM(B16:B18))^(('Guzzardi et al. (2024)'!G30-1)/'Guzzardi et al. (2024)'!G30))*SUM(B16:B18)-B17*D17-B18*D18)/B16 -> 3123712.2 | E16: =D16/'Guzzardi et al. (2024)'!G$30 -> 1325954.2 | F16: ='Guzzardi et al. (2024)'!C11 - (1/3)*('Guzzardi et al. (2024)'!C11 - 'Guzzardi et al. (2024)'!C12) -> 0.3 | G16: =F16*('Guzzardi et al. (2024)'!D$11/'Guzzardi et al. (2024)'!C$11) -> 0.125 | H16: 0.083 | I16: =WID!O27 -> 0.068384531 | J16: =WID!O58 -> 0.065689781 | K16: =WID!O$70 -> -8.4327136e-05 | L16: =H16*G16 -> 0.010375 | M16: =D16*(1+I16)^10 -> 6052669 | N16: =E16*(1+J16)^10 -> 2505166.2 | O16: =(N16/H16)/1000000 -> 30.182725 | P16: =M16/(M16-N16) -> 1.7061773 | Q16: =P16*(1-(N16/N17)^(P16-1)) -> 1.099074 | R16: =MIN(1,MAX((M$22^(-Q16+1)-O17^(-Q16+1))/(O16^(-Q16+1)-O17^(-Q16+1)),0)) -> 0 | S16: =MIN(1,MAX((M$22^(-Q16)-O17^(-Q16))/(O16^(-Q16)-O17^(-Q16)),0))*B16*(1+K16)^6 -> 0 | T16: =F16 -> 0.3 | U16: =F16+MAX(0,M$23/H16-G16)*R16 -> 0.3 | V16: =(U16-T16)*M16*B16*(1+K16)^10/1000000 -> 0
A17: P99.999-Billionaires | B17: ='Guzzardi et al. (2024)'!C30*0.009 -> 456.291 | C17: =(B17*D17)/(D$14*B$14/C$14) -> 0.0041122132 | D17: =(('Guzzardi et al. (2024)'!E30*(SUM(B15:B18)/SUM(B17:B18))^(('Guzzardi et al. (2024)'!G30-1)/'Guzzardi et al. (2024)'!G30))*(B17+B18)-B18*D18)/B17 -> 11961492 | E17: =D17/'Guzzardi et al. (2024)'!G$30 -> 5077417.6 | F17: ='Guzzardi et al. (2024)'!C11 - (2/3)*('Guzzardi et al. (2024)'!C11 - 'Guzzardi et al. (2024)'!C12) -> 0.24 | G17: =F17*('Guzzardi et al. (2024)'!D$11/'Guzzardi et al. (2024)'!C$11) -> 0.1 | H17: 0.074 | I17: =WID!O28 -> 0.081211274 | J17: =WID!O59 -> 0.078617252 | K17: =WID!O$70 -> -8.4327136e-05 | L17: =H17*G17 -> 0.0074 | M17: =D17*(1+I17)^10 -> 26115060 | N17: =E17*(1+J17)^10 -> 10822224 | O17: =(N17/H17)/1000000 -> 146.24627 | P17: =M17/(M17-N17) -> 1.7076662 | Q17: =P17*(1-(N17/N18)^(P17-1)) -> 1.2067747 | R17: =MIN(1,MAX((M$22^(-Q17+1)-O18^(-Q17+1))/(O17^(-Q17+1)-O18^(-Q17+1)),0)) -> 0.14725955 | S17: =MIN(1,MAX((M$22^(-Q17)-O18^(-Q17))/(O17^(-Q17)-O18^(-Q17)),0))*B17*(1+K17)^6 -> 19.136171 | T17: =F17 -> 0.24 | U17: =F17+MAX(0,M$23/H17-G17)*R17 -> 0.26507392 | V17: =(U17-T17)*M17*B17*(1+K17)^10/1000000 -> 298.53069
A18: Billionaires | B18: ='Guzzardi et al. (2024)'!C30*0.0009 -> 45.6291 | C18: =(B18*D18)/(D$14*B$14/C$14) -> 0.0023268806 | D18: ='Guzzardi et al. (2024)'!E30*(SUM(B15:B18)/B18)^(('Guzzardi et al. (2024)'!G30-1)/'Guzzardi et al. (2024)'!G30) -> 67683662 | E18: =D18/'Guzzardi et al. (2024)'!G$30 -> 28730379 | F18: ='Guzzardi et al. (2024)'!C12 -> 0.18 | G18: =F18*('Guzzardi et al. (2024)'!D$11/'Guzzardi et al. (2024)'!C$11) -> 0.075 | H18: 0.04 | I18: =WID!O28 -> 0.081211274 | J18: =WID!O59 -> 0.078617252 | K18: =WID!O$70 -> -8.4327136e-05 | L18: =H18*G18 -> 0.003 | M18: =D18*(1+I18)^10 -> 1.477711e+08 | N18: =E18*(1+J18)^10 -> 61237152 | O18: =(N18/H18)/1000000 -> 1530.9288 | P18: =M18/(M18-N18) -> 1.7076662 | R18: =IF(M$22<=O18, 1, (O18/M$22)^(P18-1)) -> 1 | S18: =IF(M$22<=O18, 1, (O18/M$22)^P18)*B18*(1+K18)^6 -> 45.606018 | T18: 0.26 | U18: =T18+MAX(0,M$23/H18-G18)*R18 -> 0.685 | V18: =(U18-T18)*M18*B18*(1+K18)^10/1000000 -> 2863.2158
S19: =SUM(S14:S18) -> 64.742189 | V19: =SUM(V14:V18) -> 3161.7465
B20: Sources: Guzzardi et al. (2024). See formulas.
B21: Notes: The tax rate estimate for billionaires comes from one single observation (Silvio Berlusconi in 2020) | L21: Reform Parameters | T21: Summary of revenu estimates
B22: Tax rate estimates for P99.99-P99.999 and for P99.999-Billionnaires are linearly interpolated. | L22: Threshold | M22: 1000 | T22: =V19 -> 3161.7465 | U22: 0.02 | V22: 0.03
B23: Tax rates for groups P10-P20 and P20-P30 are taken equal to the tax rate estimate for P25-P50. | L23: Rate | M23: 0.02 | T23: 100 | U23: 5616.1741 | V23: 9663.332
B24: Individual tax rates for the top three income groups are calculated by extrapolating the individual tax rate to total tax rate ratio observed for P99.99-P100. | T24: 1000 | U24: 3161.7465 | V24: 5082.9203
B25: For dissagregating income values within the top 0.1%, we assume a Pareto distribution.
B26: For dissagregating income shares within the bottom 50%, we apply the incomes shares observed in France (Bach et al., 2025).

Sheet Summary
B2: Revenue estimates (above) for different wealth tax scenarios, and comparison with previous estimates (below)
C3: 2% rate | E3: 3% rate | H3: Comments
C4: Centi-millionaires | D4: Billionaires | E4: Centi-millionaires | F4: Billionaires
B5: United States | C5: =USA!U23/1000 -> 115.51745 | D5: =USA!U24/1000 -> 93.787937 | E5: =USA!V23/1000 -> 303.13347 | F5: =USA!V24/1000 -> 183.34885 | H5: Non-billionaires already face effective personal wealth tax rate larger than 2%, so they are only taxed in the 3% scenario and generate few revenues.
C6: 145.6 | D6: 94 | E6: 288.3 | F6: 161.1
B7: France | C7: =FRA!U23/1000 -> 16.983738 | D7: =FRA!U24/1000 -> 13.070687 | E7: =FRA!V23/1000 -> 28.076523 | F7: =FRA!V24/1000 -> 20.367647 | H7: Billionaires estimates coincide very well.
C8: 19.4 | D8: 12.5 | E8: 34.8 | F8: 19.5
B9: Netherlands | C9: =NDL!U23/1000 -> 4.2723834 | D9: =NDL!U24/1000 -> 0.91587086 | E9: =NDL!V23/1000 -> 6.7203525 | F9: =NDL!V24/1000 -> 1.3875362 | H9: Current wealth tax rate (0,03% for the top income group) lower than the 0,2% hypothesis used in previous estimates. Significant centimilionnaires estimate discrepancy because current simulation capture numerous centimillionaires with low effective tax rates.
C10: 1 | D10: 0.6 | E10: 1.7 | F10: 1
B11: Italy | C11: =ITA!U23/1000 -> 5.6161741 | D11: =ITA!U24/1000 -> 3.1617465 | E11: =ITA!V23/1000 -> 9.663332 | F11: =ITA!V24/1000 -> 5.0829203 | H11: High billionaire wealth in Forbes compared to income concentration in income data. Reconcilied with higher income to wealth ratio assumption than Forbes calibration.
C12: 8.3 | D12: 5.4 | E12: 15 | F12: 8.4
B13: Brazil | C13: =BRA!U23/1000 -> 16.658255 | D13: =BRA!U24/1000 -> 5.6152889 | E13: =BRA!V23/1000 -> 25.773375 | F13: =BRA!V24/1000 -> 8.6732001 | H13: Low billionaire wealth in Forbes compared to income concentration in income data. Reconcilied with lower income to wealth ratio assumption than Forbes calibration.
C14: 5.5 | D14: 3.5 | E14: 9.8 | F14: 5.5
B16: Notes: Amounts are €B for France, Netherlands, Italy, and $B for US and Brazil.
B17: Previous estimates use Real-Time Billionaire data from Forbes (retrieved on March 3, 2025).
B18: They assume a current effective tax rate of billionaires equal to 0.2% (0,6% for the US) of their wealth,
B19: and use a simple multiplicative factors of 1.55 (for 2% rate) and 1.79 (for 3% rate) when moving from revenue for billionaires to revenue for centi-millionaires.
B20: Current estimates start from country specific estimates of income distribution and tax progressivity for year 2025.
B21: They apply decreasing income to wealth ratio at the top of the distribution.
B23: The 1,55 multiplication rule from previous estimates is contradicted by simulations based on country-specific income distributions. This explains the estimation discrepancies for centi-millionaires scenarios.
B25: When the chosen income to wealth ratio is closed to the Forbes calibrated one, billionnaires estimates are very close to previous estimates.
B26: When the chosen income to wealth ratio is larger (smaller) than the Forbes calibrated one, billionnaires estimates are lower (higher) than previous estimates.
B27: There is therefore a trade-off between the confidence we can place in the Forbes data (timely and based on observed wealth, but uncertain coverage and limited granularity)
B28: and the information conveyed by income distributions (no direct wealth data, but broad coverage, well-defined granularity, and direct connection to tax rate estimates).

Sheet Data Sources
A2: LIST OF DATA SOURCES
A4: Laurent Bach, Antoine Bozio, Arthur Guillouzouic, Clément Malgouyres (2025). Do Billionaires Pay Taxes?
A5: Insee (2024). Comptes nationaux distribués 2022, base 2020. CND.101 - Comptes nationaux distribués selon les vingtièmes de niveau de vie usuel
A6: Thomas Piketty, Emmanuel Saez, Gabriel Zucman (2018). Distributional National Accounts: Methods and Estimates for the United States.
